{"trial_id": "00", "hyperparameters": {"space": [{"class_name": "Int", "config": {"name": "num_layers", "default": 3, "conditions": [], "min_value": 2, "max_value": 5, "step": 1, "sampling": "linear"}}, {"class_name": "Int", "config": {"name": "units", "default": 64, "conditions": [], "min_value": 32, "max_value": 256, "step": 32, "sampling": "linear"}}, {"class_name": "Choice", "config": {"name": "activation", "default": "relu", "conditions": [], "values": ["relu", "tanh", "sigmoid"], "ordered": false}}, {"class_name": "Choice", "config": {"name": "optimizers", "default": "adam", "conditions": [], "values": ["adam", "sgd"], "ordered": false}}, {"class_name": "Float", "config": {"name": "lr", "default": 0.001, "conditions": [], "min_value": 0.0001, "max_value": 0.01, "step": null, "sampling": "log"}}], "values": {"num_layers": 3, "units": 64, "activation": "relu", "optimizers": "adam", "lr": 0.001}}, "metrics": {"metrics": {}}, "score": null, "best_step": 0, "status": "FAILED", "message": "Traceback (most recent call last):\n  File \"/home/vietanhdong/anaconda3/envs/tf-gpu/lib/python3.12/site-packages/keras_tuner/src/engine/base_tuner.py\", line 274, in _try_run_and_update_trial\n    self._run_and_update_trial(trial, *fit_args, **fit_kwargs)\n  File \"/home/vietanhdong/anaconda3/envs/tf-gpu/lib/python3.12/site-packages/keras_tuner/src/engine/base_tuner.py\", line 239, in _run_and_update_trial\n    results = self.run_trial(trial, *fit_args, **fit_kwargs)\n              ^^^^^^^^^^^^^^^^^^^^^^^^^^^^^^^^^^^^^^^^^^^^^^\n  File \"/home/vietanhdong/anaconda3/envs/tf-gpu/lib/python3.12/site-packages/keras_tuner/src/engine/tuner.py\", line 314, in run_trial\n    obj_value = self._build_and_fit_model(trial, *args, **copied_kwargs)\n                ^^^^^^^^^^^^^^^^^^^^^^^^^^^^^^^^^^^^^^^^^^^^^^^^^^^^^^^^\n  File \"/home/vietanhdong/anaconda3/envs/tf-gpu/lib/python3.12/site-packages/keras_tuner/src/engine/tuner.py\", line 233, in _build_and_fit_model\n    results = self.hypermodel.fit(hp, model, *args, **kwargs)\n              ^^^^^^^^^^^^^^^^^^^^^^^^^^^^^^^^^^^^^^^^^^^^^^^\n  File \"/home/vietanhdong/anaconda3/envs/tf-gpu/lib/python3.12/site-packages/keras_tuner/src/engine/hypermodel.py\", line 149, in fit\n    return model.fit(*args, **kwargs)\n           ^^^^^^^^^^^^^^^^^^^^^^^^^^\n  File \"/home/vietanhdong/anaconda3/envs/tf-gpu/lib/python3.12/site-packages/keras/src/utils/traceback_utils.py\", line 122, in error_handler\n    raise e.with_traceback(filtered_tb) from None\n  File \"/home/vietanhdong/anaconda3/envs/tf-gpu/lib/python3.12/site-packages/keras/src/callbacks/model_checkpoint.py\", line 323, in _get_file_path\n    raise KeyError(\nKeyError: 'Failed to format this callback filepath: \"best_tuner_{datetime.datetime.now().strftime(\"%Y%m%d-%H%M%S\")}.keras\". Reason: \\'datetime\\''\n"}